29/10/20 (10:06:16) | ERROR: Input thread failed with exception: 'utf-8' codec can't decode byte 0xb8 in position 4: invalid start byte
Traceback (most recent call last):
  File "/usr/bin/bpytop", line 821, in _get_key
    input_key += sys.stdin.read(1)						#* Read 1 key safely with blocking on
  File "/usr/lib/python3.8/codecs.py", line 322, in decode
    (result, consumed) = self._buffer_decode(data, self.errors, final)
UnicodeDecodeError: 'utf-8' codec can't decode byte 0xb8 in position 4: invalid start byte
29/10/20 (10:06:17) | WARNING: Exiting with errorcode (1). Runtime 0:02:42 

29/10/20 (12:01:24) | ERROR: Input thread failed with exception: (5, 'Input/output error')
Traceback (most recent call last):
  File "/usr/bin/bpytop", line 869, in _get_key
    input_key = ""
  File "/usr/bin/bpytop", line 662, in __exit__
    termios.tcsetattr(self.stream, termios.TCSANOW, self.original_stty)
termios.error: (5, 'Input/output error')
29/10/20 (12:01:25) | ERROR: [Errno 5] Input/output error
Traceback (most recent call last):
  File "/usr/bin/bpytop", line 4897, in main
    run()
  File "/usr/bin/bpytop", line 4890, in run
    if Key.input_wait(Timer.left()):
  File "/usr/bin/bpytop", line 795, in input_wait
    cls.new.wait(sec if sec > 0 else 0.0)
  File "/usr/lib/python3.8/threading.py", line 558, in wait
    signaled = self._cond.wait(timeout)
  File "/usr/lib/python3.8/threading.py", line 306, in wait
    gotit = waiter.acquire(True, timeout)
  File "/usr/bin/bpytop", line 4514, in quit_sigint
    clean_quit()
  File "/usr/bin/bpytop", line 4527, in clean_quit
    Draw.now(Term.clear, Term.normal_screen, Term.show_cursor, Term.mouse_off, Term.mouse_direct_off, Term.title())
  File "/usr/bin/bpytop", line 903, in now
    print(*args, sep="", end="", flush=True)
OSError: [Errno 5] Input/output error
29/10/20 (15:39:55) | ERROR: <urlopen error timed out>
Traceback (most recent call last):
  File "/usr/lib/python3.8/urllib/request.py", line 1350, in do_open
    h.request(req.get_method(), req.selector, req.data, headers,
  File "/usr/lib/python3.8/http/client.py", line 1255, in request
    self._send_request(method, url, body, headers, encode_chunked)
  File "/usr/lib/python3.8/http/client.py", line 1301, in _send_request
    self.endheaders(body, encode_chunked=encode_chunked)
  File "/usr/lib/python3.8/http/client.py", line 1250, in endheaders
    self._send_output(message_body, encode_chunked=encode_chunked)
  File "/usr/lib/python3.8/http/client.py", line 1010, in _send_output
    self.send(msg)
  File "/usr/lib/python3.8/http/client.py", line 950, in send
    self.connect()
  File "/usr/lib/python3.8/http/client.py", line 1417, in connect
    super().connect()
  File "/usr/lib/python3.8/http/client.py", line 921, in connect
    self.sock = self._create_connection(
  File "/usr/lib/python3.8/socket.py", line 808, in create_connection
    raise err
  File "/usr/lib/python3.8/socket.py", line 796, in create_connection
    sock.connect(sa)
socket.timeout: timed out

During handling of the above exception, another exception occurred:

Traceback (most recent call last):
  File "/usr/bin/bpytop", line 4302, in _checker
    with urllib.request.urlopen("https://github.com/aristocratos/bpytop/raw/master/bpytop.py", timeout=5) as source: # type: ignore
  File "/usr/lib/python3.8/urllib/request.py", line 222, in urlopen
    return opener.open(url, data, timeout)
  File "/usr/lib/python3.8/urllib/request.py", line 525, in open
    response = self._open(req, data)
  File "/usr/lib/python3.8/urllib/request.py", line 542, in _open
    result = self._call_chain(self.handle_open, protocol, protocol +
  File "/usr/lib/python3.8/urllib/request.py", line 502, in _call_chain
    result = func(*args)
  File "/usr/lib/python3.8/urllib/request.py", line 1393, in https_open
    return self.do_open(http.client.HTTPSConnection, req,
  File "/usr/lib/python3.8/urllib/request.py", line 1353, in do_open
    raise URLError(err)
urllib.error.URLError: <urlopen error timed out>
31/10/20 (12:26:27) | ERROR: <urlopen error timed out>
Traceback (most recent call last):
  File "/usr/lib/python3.8/urllib/request.py", line 1350, in do_open
    h.request(req.get_method(), req.selector, req.data, headers,
  File "/usr/lib/python3.8/http/client.py", line 1255, in request
    self._send_request(method, url, body, headers, encode_chunked)
  File "/usr/lib/python3.8/http/client.py", line 1301, in _send_request
    self.endheaders(body, encode_chunked=encode_chunked)
  File "/usr/lib/python3.8/http/client.py", line 1250, in endheaders
    self._send_output(message_body, encode_chunked=encode_chunked)
  File "/usr/lib/python3.8/http/client.py", line 1010, in _send_output
    self.send(msg)
  File "/usr/lib/python3.8/http/client.py", line 950, in send
    self.connect()
  File "/usr/lib/python3.8/http/client.py", line 1417, in connect
    super().connect()
  File "/usr/lib/python3.8/http/client.py", line 921, in connect
    self.sock = self._create_connection(
  File "/usr/lib/python3.8/socket.py", line 808, in create_connection
    raise err
  File "/usr/lib/python3.8/socket.py", line 796, in create_connection
    sock.connect(sa)
socket.timeout: timed out

During handling of the above exception, another exception occurred:

Traceback (most recent call last):
  File "/usr/bin/bpytop", line 4306, in _checker
    with urllib.request.urlopen("https://github.com/aristocratos/bpytop/raw/master/bpytop.py", timeout=5) as source: # type: ignore
  File "/usr/lib/python3.8/urllib/request.py", line 222, in urlopen
    return opener.open(url, data, timeout)
  File "/usr/lib/python3.8/urllib/request.py", line 531, in open
    response = meth(req, response)
  File "/usr/lib/python3.8/urllib/request.py", line 640, in http_response
    response = self.parent.error(
  File "/usr/lib/python3.8/urllib/request.py", line 563, in error
    result = self._call_chain(*args)
  File "/usr/lib/python3.8/urllib/request.py", line 502, in _call_chain
    result = func(*args)
  File "/usr/lib/python3.8/urllib/request.py", line 755, in http_error_302
    return self.parent.open(new, timeout=req.timeout)
  File "/usr/lib/python3.8/urllib/request.py", line 525, in open
    response = self._open(req, data)
  File "/usr/lib/python3.8/urllib/request.py", line 542, in _open
    result = self._call_chain(self.handle_open, protocol, protocol +
  File "/usr/lib/python3.8/urllib/request.py", line 502, in _call_chain
    result = func(*args)
  File "/usr/lib/python3.8/urllib/request.py", line 1393, in https_open
    return self.do_open(http.client.HTTPSConnection, req,
  File "/usr/lib/python3.8/urllib/request.py", line 1353, in do_open
    raise URLError(err)
urllib.error.URLError: <urlopen error timed out>
06/11/20 (07:36:10) | ERROR: <urlopen error [Errno -3] Temporary failure in name resolution>
Traceback (most recent call last):
  File "/usr/lib/python3.8/urllib/request.py", line 1350, in do_open
    h.request(req.get_method(), req.selector, req.data, headers,
  File "/usr/lib/python3.8/http/client.py", line 1255, in request
    self._send_request(method, url, body, headers, encode_chunked)
  File "/usr/lib/python3.8/http/client.py", line 1301, in _send_request
    self.endheaders(body, encode_chunked=encode_chunked)
  File "/usr/lib/python3.8/http/client.py", line 1250, in endheaders
    self._send_output(message_body, encode_chunked=encode_chunked)
  File "/usr/lib/python3.8/http/client.py", line 1010, in _send_output
    self.send(msg)
  File "/usr/lib/python3.8/http/client.py", line 950, in send
    self.connect()
  File "/usr/lib/python3.8/http/client.py", line 1417, in connect
    super().connect()
  File "/usr/lib/python3.8/http/client.py", line 921, in connect
    self.sock = self._create_connection(
  File "/usr/lib/python3.8/socket.py", line 787, in create_connection
    for res in getaddrinfo(host, port, 0, SOCK_STREAM):
  File "/usr/lib/python3.8/socket.py", line 918, in getaddrinfo
    for res in _socket.getaddrinfo(host, port, family, type, proto, flags):
socket.gaierror: [Errno -3] Temporary failure in name resolution

During handling of the above exception, another exception occurred:

Traceback (most recent call last):
  File "/usr/bin/bpytop", line 4315, in _checker
    with urllib.request.urlopen("https://github.com/aristocratos/bpytop/raw/master/bpytop.py", timeout=5) as source: # type: ignore
  File "/usr/lib/python3.8/urllib/request.py", line 222, in urlopen
    return opener.open(url, data, timeout)
  File "/usr/lib/python3.8/urllib/request.py", line 525, in open
    response = self._open(req, data)
  File "/usr/lib/python3.8/urllib/request.py", line 542, in _open
    result = self._call_chain(self.handle_open, protocol, protocol +
  File "/usr/lib/python3.8/urllib/request.py", line 502, in _call_chain
    result = func(*args)
  File "/usr/lib/python3.8/urllib/request.py", line 1393, in https_open
    return self.do_open(http.client.HTTPSConnection, req,
  File "/usr/lib/python3.8/urllib/request.py", line 1353, in do_open
    raise URLError(err)
urllib.error.URLError: <urlopen error [Errno -3] Temporary failure in name resolution>
